sqlalchemy.exc.OperationalError: (psycopg2.OperationalError) SSL connection has been closed unexpectedly [SQL: SELECT simulation_runs.id AS simulation_runs_id, simulation_runs.name AS simulation_runs_name, simulation_runs.description AS simulation_runs_description, simulation_runs.created_at AS simulation_runs_created_at, simulation_runs.grid_size AS simulation_runs_grid_size, simulation_runs.resources AS simulation_runs_resources, simulation_runs.dangers AS simulation_runs_dangers, simulation_runs.goals AS simulation_runs_goals, simulation_runs.steps AS simulation_runs_steps, simulation_runs.agent_a_start_x AS simulation_runs_agent_a_start_x, simulation_runs.agent_a_start_y AS simulation_runs_agent_a_start_y, simulation_runs.agent_b_start_x AS simulation_runs_agent_b_start_x, simulation_runs.agent_b_start_y AS simulation_runs_agent_b_start_y, simulation_runs.relationship_score AS simulation_runs_relationship_score, simulation_runs.avg_resonance AS simulation_runs_avg_resonance, simulation_runs.avg_bond_strength_a AS simulation_runs_avg_bond_strength_a, simulation_runs.avg_bond_strength_b AS simulation_runs_avg_bond_strength_b, simulation_runs.agent_positions AS simulation_runs_agent_positions, simulation_runs.grid_data AS simulation_runs_grid_data, simulation_runs.full_log AS simulation_runs_full_log FROM simulation_runs ORDER BY simulation_runs.created_at DESC] (Background on this error at: https://sqlalche.me/e/20/e3q8)
Traceback:
File "/home/runner/workspace/.pythonlibs/lib/python3.11/site-packages/streamlit/runtime/scriptrunner/exec_code.py", line 121, in exec_func_with_error_handling
    result = func()
             ^^^^^^
File "/home/runner/workspace/.pythonlibs/lib/python3.11/site-packages/streamlit/runtime/scriptrunner/script_runner.py", line 639, in code_to_exec
    _mpa_v1(self._main_script_path)
File "/home/runner/workspace/.pythonlibs/lib/python3.11/site-packages/streamlit/runtime/scriptrunner/script_runner.py", line 159, in _mpa_v1
    page.run()
File "/home/runner/workspace/.pythonlibs/lib/python3.11/site-packages/streamlit/navigation/page.py", line 297, in run
    exec(code, module.__dict__)
File "/home/runner/workspace/pages/saved_simulations.py", line 27, in <module>
    simulations = database.get_all_simulations()
                  ^^^^^^^^^^^^^^^^^^^^^^^^^^^^^^
File "/home/runner/workspace/database.py", line 106, in get_all_simulations
    simulations = session.query(SimulationRun).order_by(SimulationRun.created_at.desc()).all()
                  ^^^^^^^^^^^^^^^^^^^^^^^^^^^^^^^^^^^^^^^^^^^^^^^^^^^^^^^^^^^^^^^^^^^^^^^^^^^^
File "/home/runner/workspace/.pythonlibs/lib/python3.11/site-packages/sqlalchemy/orm/query.py", line 2704, in all
    return self._iter().all()  # type: ignore
           ^^^^^^^^^^^^
File "/home/runner/workspace/.pythonlibs/lib/python3.11/site-packages/sqlalchemy/orm/query.py", line 2858, in _iter
    result: Union[ScalarResult[_T], Result[_T]] = self.session.execute(
                                                  ^^^^^^^^^^^^^^^^^^^^^
File "/home/runner/workspace/.pythonlibs/lib/python3.11/site-packages/sqlalchemy/orm/session.py", line 2365, in execute
    return self._execute_internal(
           ^^^^^^^^^^^^^^^^^^^^^^^
File "/home/runner/workspace/.pythonlibs/lib/python3.11/site-packages/sqlalchemy/orm/session.py", line 2251, in _execute_internal
    result: Result[Any] = compile_state_cls.orm_execute_statement(
                          ^^^^^^^^^^^^^^^^^^^^^^^^^^^^^^^^^^^^^^^^
File "/home/runner/workspace/.pythonlibs/lib/python3.11/site-packages/sqlalchemy/orm/context.py", line 306, in orm_execute_statement
    result = conn.execute(
             ^^^^^^^^^^^^^
File "/home/runner/workspace/.pythonlibs/lib/python3.11/site-packages/sqlalchemy/engine/base.py", line 1416, in execute
    return meth(
           ^^^^^
File "/home/runner/workspace/.pythonlibs/lib/python3.11/site-packages/sqlalchemy/sql/elements.py", line 523, in _execute_on_connection
    return connection._execute_clauseelement(
           ^^^^^^^^^^^^^^^^^^^^^^^^^^^^^^^^^^
File "/home/runner/workspace/.pythonlibs/lib/python3.11/site-packages/sqlalchemy/engine/base.py", line 1638, in _execute_clauseelement
    ret = self._execute_context(
          ^^^^^^^^^^^^^^^^^^^^^^
File "/home/runner/workspace/.pythonlibs/lib/python3.11/site-packages/sqlalchemy/engine/base.py", line 1843, in _execute_context
    return self._exec_single_context(
           ^^^^^^^^^^^^^^^^^^^^^^^^^^
File "/home/runner/workspace/.pythonlibs/lib/python3.11/site-packages/sqlalchemy/engine/base.py", line 1983, in _exec_single_context
    self._handle_dbapi_exception(
File "/home/runner/workspace/.pythonlibs/lib/python3.11/site-packages/sqlalchemy/engine/base.py", line 2352, in _handle_dbapi_exception
    raise sqlalchemy_exception.with_traceback(exc_info[2]) from e
File "/home/runner/workspace/.pythonlibs/lib/python3.11/site-packages/sqlalchemy/engine/base.py", line 1964, in _exec_single_context
    self.dialect.do_execute(
File "/home/runner/workspace/.pythonlibs/lib/python3.11/site-packages/sqlalchemy/engine/default.py", line 945, in do_execute
    cursor.execute(statement, parameters)